<?xml version='1.0' encoding='utf-8'?>
<robot name="ngr">
  
  
  
  
  
  
  
  
  
  
  
  
  <material name="darkgray">
    <color rgba="0.1 0.1 0.1 1.0" />
  </material>
  <material name="silver">
    <color rgba="0.3 0.3 0.3 1.0" />
  </material>
  <material name="red">
    <color rgba="0.8 0.0 0.2 1.0" />
  </material>
  
  <link name="body_spirit0">
    <visual>
      <origin rpy="0 0 0" xyz="0 0 0" />
      <geometry>
        <box size="0.335 0.24 0.104" />
      </geometry>
      <material name="darkgray" />
    </visual>
    <inertial>
      <mass value="5.75" />
      
      
      <inertia ixx="0.05" ixy="0" ixz="0" iyy="0.1" iyz="0" izz="0.1" />
    </inertial>
    
    <collision>
      <origin rpy="0 0 0" xyz="0 0 0" />
      <geometry>
        <box size="0.335 0.24 0.104" />
      </geometry>
    </collision>
  </link>

  <link name="arm0_base_spirit0">
  <visual>
  	<origin rpy="0 0 0" xyz="0 0 -.1875" />
  	<geometry>
  	  <cylinder radius=".025" length=".375" />
  	 </geometry>
    <material name="orange">
	   <color rgba="0.945 0.35 0.133 1.0" />
	  </material>
  </visual>
  <inertial>
     <mass value=".01" />
     <inertia ixx=".01" ixy="0" ixz="0" iyy=".001" iyz="0" izz=".01" />
  </inertial>
  <collision>
    	<origin rpy="0 0 0" xyz="0 0 -.1875" />
  	<geometry>
  	  <cylinder radius=".025" length=".375" />
  	 </geometry>
  </collision>
  </link>

  <link name="arm0_twist_spirit0">
  <visual>
  	<origin rpy="0 0 0" xyz="0 0 -.55" />
  	<geometry>
  	  <cylinder radius=".025" length=".375" />
  	 </geometry>
    <material name="orange">
	   <color rgba="0.945 0.35 0.133 1.0" />
	  </material>
  </visual>
  <inertial>
     <mass value=".01" />
     <inertia ixx=".01" ixy="0" ixz="0" iyy=".001" iyz="0" izz=".01" />
  </inertial>
  <collision>
    	<origin rpy="0 0 0" xyz="0 0 -.55" />
  	<geometry>
  	  <cylinder radius=".025" length=".375" />
  	 </geometry>
  </collision>
  </link>

  <link name="arm0_extension_spirit0">
  <visual>
  	<origin rpy="0 0 0" xyz="0 0 0" />
  	<geometry>
  	  <cylinder radius=".025" length=".75" />
  	 </geometry>
    <material name="orange">
	   <color rgba="0.945 0.35 0.133 1.0" />
	  </material>
  </visual>
  <inertial>
     <mass value=".01" />
     <inertia ixx=".01" ixy="0" ixz="0" iyy=".001" iyz="0" izz=".01" />
  </inertial>
  <collision>
    	<origin rpy="0 0 0" xyz="0 0 0" />
  	<geometry>
  	  <cylinder radius=".025" length=".75" />
  	 </geometry>
  </collision>
  </link>

  <link name="arm0_base_turret_spirit0">
  <visual>
  <origin rpy="0 0 0" xyz="0 0 0" />
  	<geometry>
  	  <cylinder radius=".1" length=".05" />
  	 </geometry>
    <material name="orange">
	   <color rgba="0.945 0.35 0.133 1.0" />
	  </material>
  </visual>
  <inertial>
     <mass value=".01" />
     <inertia ixx=".01" ixy="0" ixz="0" iyy=".001" iyz="0" izz=".01" />
  </inertial>
  <collision>
    	<origin rpy="0 0 0" xyz="0 0 0" />
  	<geometry>
  	  <cylinder radius=".1" length=".05" />
  	 </geometry>
  </collision>
  </link>

  <link name="arm0_extension_turret_spirit0">
  <visual>
  <origin rpy="0 0 0" xyz="0 0 0" />
  	<geometry>
  	  <cylinder radius=".1" length=".05" />
  	 </geometry>
    <material name="orange">
	   <color rgba="0.945 0.35 0.133 1.0" />
	  </material>
  </visual>
  <inertial>
     <mass value=".01" />
     <inertia ixx=".01" ixy="0" ixz="0" iyy=".001" iyz="0" izz=".01" />
  </inertial>
  <collision>
    	<origin rpy="0 0 0" xyz="0 0 0" />
  	<geometry>
  	  <cylinder radius=".1" length=".05" />
  	 </geometry>
  </collision>
  </link>

  <link name="arm0_block_spirit0">
  <visual>
  <origin rpy="0 0 0" xyz="0 0 0" />
  	<geometry>
  	  <box size=".05 .05 .05" />
  	 </geometry>
     <material name="red" />
  </visual>
  <inertial>
     <mass value=".01" />
     <inertia ixx=".01" ixy="0" ixz="0" iyy=".001" iyz="0" izz=".01" />
  </inertial>
  <collision>
    	<origin rpy="0 0 0" xyz="0 0 0" />
  	<geometry>
  	    <box size=".05 .05 .05" />
  	 </geometry>
  </collision>
  </link>

  <joint name="body_to_arm0_turret_spirit0" type="continuous">
  	<parent link="body_spirit0" />
  	<child link="arm0_base_turret_spirit0" />
  	<axis xyz="0 0 1" />
  	<origin xyz=".2 0 0" rpy="0 0 0" />
  </joint>

  <joint name="arm0_base_to_turret_spirit0" type="continuous">
  	<parent link="arm0_base_turret_spirit0" />
  	<child link="arm0_base_spirit0" />
  	<axis xyz="0 1 0" />
  	<origin xyz="0 0 0" rpy="0 0 0" />
  </joint>
  
  <joint name="arm0_base_to_twist_spirit0" type="continuous">
  	<parent link="arm0_base_spirit0" />
  	<child link="arm0_twist_spirit0" />
  	<axis xyz="0 0 1" />
  	<origin xyz="0 0 0" rpy="0 0 0" />
  </joint>

  <joint name="arm0_twist_to_extension_spirit0" type="prismatic">
  	<parent link="arm0_twist_spirit0" />
  	<child link="arm0_extension_spirit0" />
  	<origin xyz="0 0 -1.15" rpy="0 0 0" />
    <limit effort="1000" lower="-0.707" upper="0.707" velocity="300" />
  </joint>
  
  <joint name="arm0_extension_to_turret_spirit0" type="continuous">
  	<parent link="arm0_extension_spirit0" />
  	<child link="arm0_extension_turret_spirit0" />
  	<axis xyz="0 1 0" />
  	<origin xyz="0 0 -.375" rpy="0 0 0" />
  </joint>
  
  <joint name="arm0_extension_turret_to_block_spirit0" type="continuous">
  	<parent link="arm0_extension_turret_spirit0" />
  	<child link="arm0_block_spirit0" />
  	<axis xyz="0 0 1" />
  	<origin xyz="0 0 -.08" rpy="0 0 0" />
  </joint>

  <gazebo reference="body">
    <material>Gazebo/BlackTransparent</material>
  </gazebo>
  <gazebo reference="body">
    <gravity>true</gravity>
    <sensor name="imu_sensor" type="imu">
      <always_on>true</always_on>
      <update_rate>100</update_rate>
      <visualize>true</visualize>
      <topic>__default_topic_</topic>
      <plugin filename="libgazebo_ros_imu_sensor.so" name="imu_plugin">
        <topicName>imu</topicName>
        <bodyName>body</bodyName>
        <updateRateHZ>100.0</updateRateHZ>
        <gaussianNoise>0.0</gaussianNoise>
        <xyzOffset>0 0 0</xyzOffset>
        <rpyOffset>0 0 0</rpyOffset>
        <frameName>body</frameName>
        <initialOrientationAsReference>false</initialOrientationAsReference>
      </plugin>
      <pose>0 0 0 0 0 0</pose>
    </sensor>
  </gazebo>
  
  
  
  <link name="hip0_spirit0">
    <visual>
      <origin rpy="1.5707963268 0 0" xyz="0.0 0.028 0" />
      <geometry>
        <cylinder length="0.08" radius="0.055" />
      </geometry>
      <material name="darkgray" />
    </visual>
    <collision>
      <origin rpy="1.5707963268 0 0" xyz="0 0.028 0" />
      <geometry>
        <cylinder length="0.08" radius="0.055" />
      </geometry>
    </collision>
    <inertial>
      <mass value="0.575" />
      
      <inertia ixx="0.00066963541" ixy="0" ixz="0" iyy="0.00066963541" iyz="0" izz="0.0008696875" />
    </inertial>
  </link>
  <gazebo reference="hip0">
    <material>Gazebo/Purple</material>
  </gazebo>
  
  <joint name="8_spirit0" type="revolute">
    <parent link="body_spirit0" />
    <child link="hip0_spirit0" />
    <axis xyz="1 0 0" />
    <origin xyz="0.2263 0.07 0" />
    <limit effort="40" lower="-0.707" upper="0.707" velocity="30" />
    <dynamics damping="0.0" friction="0.0" />
  </joint>
  
  <transmission name="transmission_8">
    <type>transmission_interface/SimpleTransmission</type>
    <joint name="8_spirit0">
      <hardwareInterface>hardware_interface/EffortJointInterface</hardwareInterface>
    </joint>
    <actuator name="motor_8">
      <hardwareInterface>EffortJointInterface</hardwareInterface>
      <mechanicalReduction>1</mechanicalReduction>
    </actuator>
  </transmission>
  
  <link name="upper0_spirit0">
    <visual>
      <origin rpy="0 0 0" xyz="-0.103 -0.022 0" />
      <geometry>
        <box size="0.206 0.022 0.055" />
      </geometry>
      <material name="silver" />
    </visual>
    <collision>
      <origin rpy="0 0 0" xyz="-0.103 -0.022 0" />
      <geometry>
        <box size="0.206 0.022 0.055" />
      </geometry>
    </collision>
    <inertial>
      <mass value="0.775" />
      <inertia ixx="5e-05" ixy="0" ixz="0" iyy="0.001" iyz="0" izz="0.001" />
    </inertial>
  </link>
  <gazebo reference="upper0">
    <material>Gazebo/Blue</material>
  </gazebo>
  
  <joint name="0_spirit0" type="revolute">
    <parent link="hip0_spirit0" />
    <child link="upper0_spirit0" />
    <axis xyz="0 -1 0" />
    <origin xyz="0.0 0.10098 0" />
    
    <limit effort="40" lower="-6.28318530718" upper="6.28318530718" velocity="30" />
    <dynamics damping="0.0" friction="0.0" />
  </joint>
  
  <transmission name="transmission_0">
    <type>transmission_interface/SimpleTransmission</type>
    <joint name="0_spirit0">
      <hardwareInterface>hardware_interface/EffortJointInterface</hardwareInterface>
    </joint>
    <actuator name="motor_0">
      <hardwareInterface>EffortJointInterface</hardwareInterface>
      <mechanicalReduction>1</mechanicalReduction>
    </actuator>
  </transmission>
  
  <link name="lower0_spirit0">
    <visual>
      <origin rpy="0 1.5707963268 0" xyz="0.103 0 0" />
      <geometry>
        <cylinder length="0.206" radius="0.013" />
      </geometry>
      <material name="darkgray" />
    </visual>
    <collision>
      <origin rpy="0 1.5707963268 0" xyz="0.103 0 0" />
      <geometry>
        <cylinder length="0.206" radius="0.013" />
      </geometry>
    </collision>
    <inertial>
      <mass value="0.075" />
      <inertia ixx="5e-06" ixy="0" ixz="0" iyy="0.0001" iyz="0" izz="0.0001" />
    </inertial>
  </link>
  <gazebo reference="lower0">
    <material>Gazebo/Black</material>
  </gazebo>
  
  <joint name="1_spirit0" type="revolute">
    <parent link="upper0_spirit0" />
    <child link="lower0_spirit0" />
    <axis xyz="0 1 0" />
    <origin xyz="-0.206 0 0" />
    
    <limit effort="40" velocity="30" />
    <dynamics damping="0.0" friction="0.0" />
  </joint>
  
  <transmission name="transmission_1">
    <type>transmission_interface/SimpleTransmission</type>
    <joint name="1_spirit0">
      <hardwareInterface>hardware_interface/EffortJointInterface</hardwareInterface>
    </joint>
    <actuator name="motor_1">
      <hardwareInterface>EffortJointInterface</hardwareInterface>
      <mechanicalReduction>1</mechanicalReduction>
    </actuator>
  </transmission>
  
  <link name="toe0_spirit0">
    <contact>
      <friction_anchor />
      <stiffness value="30000.0" />
      <damping value="1000.0" />
      <spinning_friction value="0.3" />
      <lateral_friction value="3.0" />
    </contact>
    <visual>
      <origin rpy="0 0 0" xyz="0 0 0" />
      <geometry>
        <sphere radius="0.02" />
      </geometry>
      <material name="darkgray" />
    </visual>
    <collision>
      <origin rpy="0 0 0" xyz="0 0 0" />
      <geometry>
        <sphere radius="0.02" />
      </geometry>
    </collision>
    <inertial>
      <mass value="0.35" />
      <inertia ixx="0.00005" ixy="0" ixz="0" iyy="0.00005" iyz="0" izz="0.00005" />
      
    </inertial>
  </link>
  <gazebo reference="toe0">
    <material>Gazebo/DarkGray</material>
    <collision>
      <surface>
        <bounce>
          <restitution_coefficient>0</restitution_coefficient>
          <threshold>1e+06</threshold>
        </bounce>
        <friction>
          <torsional>
            <coefficient>0.3</coefficient>
          </torsional>
          <ode>
            <mu>20.0</mu>
            <mu2>3.0</mu2>
          </ode>
          <bullet>
            <rolling_friction>0.3</rolling_friction>
            <friction2>3.0</friction2>
          </bullet>
        </friction>
        <contact>
          <bullet>
            <kp>30000.0</kp>
            <kd>1000.0</kd>
          </bullet>
          <ode>
            <kp>30000.0</kp>
            <kd>1000.0</kd>
          </ode>
        </contact>
      </surface>
    </collision>
  </gazebo>
  <joint name="jtoe0_spirit0" type="fixed">
    <parent link="lower0_spirit0" />
    <child link="toe0_spirit0" />
    <origin xyz="0.206 0 -0.0" />
    <dynamics damping="0.0" friction="0.0" />
  </joint>
  
  <link name="hip1_spirit0">
    <visual>
      <origin rpy="1.5707963268 0 0" xyz="-0.0 0.028 0" />
      <geometry>
        <cylinder length="0.08" radius="0.055" />
      </geometry>
      <material name="darkgray" />
    </visual>
    <collision>
      <origin rpy="1.5707963268 0 0" xyz="0 0.028 0" />
      <geometry>
        <cylinder length="0.08" radius="0.055" />
      </geometry>
    </collision>
    <inertial>
      <mass value="0.575" />
      
      <inertia ixx="0.00066963541" ixy="0" ixz="0" iyy="0.00066963541" iyz="0" izz="0.0008696875" />
    </inertial>
  </link>
  <gazebo reference="hip1">
    <material>Gazebo/Purple</material>
  </gazebo>
  
  <joint name="9_spirit0" type="revolute">
    <parent link="body_spirit0" />
    <child link="hip1_spirit0" />
    <axis xyz="1 0 0" />
    <origin xyz="-0.2263 0.07 0" />
    <limit effort="40" lower="-0.707" upper="0.707" velocity="30" />
    <dynamics damping="0.0" friction="0.0" />
  </joint>
  
  <transmission name="transmission_9">
    <type>transmission_interface/SimpleTransmission</type>
    <joint name="9_spirit0">
      <hardwareInterface>hardware_interface/EffortJointInterface</hardwareInterface>
    </joint>
    <actuator name="motor_9">
      <hardwareInterface>EffortJointInterface</hardwareInterface>
      <mechanicalReduction>1</mechanicalReduction>
    </actuator>
  </transmission>
  
  <link name="upper1_spirit0">
    <visual>
      <origin rpy="0 0 0" xyz="-0.103 -0.022 0" />
      <geometry>
        <box size="0.206 0.022 0.055" />
      </geometry>
      <material name="silver" />
    </visual>
    <collision>
      <origin rpy="0 0 0" xyz="-0.103 -0.022 0" />
      <geometry>
        <box size="0.206 0.022 0.055" />
      </geometry>
    </collision>
    <inertial>
      <mass value="0.775" />
      <inertia ixx="5e-05" ixy="0" ixz="0" iyy="0.001" iyz="0" izz="0.001" />
    </inertial>
  </link>
  <gazebo reference="upper1">
    <material>Gazebo/Blue</material>
  </gazebo>
  
  <joint name="2_spirit0" type="revolute">
    <parent link="hip1_spirit0" />
    <child link="upper1_spirit0" />
    <axis xyz="0 -1 0" />
    <origin xyz="-0.0 0.10098 0" />
    
    <limit effort="40" lower="-6.28318530718" upper="6.28318530718" velocity="30" />
    <dynamics damping="0.0" friction="0.0" />
  </joint>
  
  <transmission name="transmission_2">
    <type>transmission_interface/SimpleTransmission</type>
    <joint name="2_spirit0">
      <hardwareInterface>hardware_interface/EffortJointInterface</hardwareInterface>
    </joint>
    <actuator name="motor_2">
      <hardwareInterface>EffortJointInterface</hardwareInterface>
      <mechanicalReduction>1</mechanicalReduction>
    </actuator>
  </transmission>
  
  <link name="lower1_spirit0">
    <visual>
      <origin rpy="0 1.5707963268 0" xyz="0.103 0 0" />
      <geometry>
        <cylinder length="0.206" radius="0.013" />
      </geometry>
      <material name="darkgray" />
    </visual>
    <collision>
      <origin rpy="0 1.5707963268 0" xyz="0.103 0 0" />
      <geometry>
        <cylinder length="0.206" radius="0.013" />
      </geometry>
    </collision>
    <inertial>
      <mass value="0.075" />
      <inertia ixx="5e-06" ixy="0" ixz="0" iyy="0.0001" iyz="0" izz="0.0001" />
    </inertial>
  </link>
  <gazebo reference="lower1">
    <material>Gazebo/Black</material>
  </gazebo>
  
  <joint name="3_spirit0" type="revolute">
    <parent link="upper1_spirit0" />
    <child link="lower1_spirit0" />
    <axis xyz="0 1 0" />
    <origin xyz="-0.206 0 0" />
    
    <limit effort="40" velocity="30" />
    <dynamics damping="0.0" friction="0.0" />
  </joint>
  
  <transmission name="transmission_3">
    <type>transmission_interface/SimpleTransmission</type>
    <joint name="3_spirit0">
      <hardwareInterface>hardware_interface/EffortJointInterface</hardwareInterface>
    </joint>
    <actuator name="motor_3">
      <hardwareInterface>EffortJointInterface</hardwareInterface>
      <mechanicalReduction>1</mechanicalReduction>
    </actuator>
  </transmission>
  
  <link name="toe1_spirit0">
    <contact>
      <friction_anchor />
      <stiffness value="30000.0" />
      <damping value="1000.0" />
      <spinning_friction value="0.3" />
      <lateral_friction value="3.0" />
    </contact>
    <visual>
      <origin rpy="0 0 0" xyz="0 0 0" />
      <geometry>
        <sphere radius="0.02" />
      </geometry>
      <material name="darkgray" />
    </visual>
    <collision>
      <origin rpy="0 0 0" xyz="0 0 0" />
      <geometry>
        <sphere radius="0.02" />
      </geometry>
    </collision>
    <inertial>
      <mass value="0.35" />
      <inertia ixx="0.00005" ixy="0" ixz="0" iyy="0.00005" iyz="0" izz="0.00005" />
      
    </inertial>
  </link>
  <gazebo reference="toe1">
    <material>Gazebo/DarkGray</material>
    <collision>
      <surface>
        <bounce>
          <restitution_coefficient>0</restitution_coefficient>
          <threshold>1e+06</threshold>
        </bounce>
        <friction>
          <torsional>
            <coefficient>0.3</coefficient>
          </torsional>
          <ode>
            <mu>20.0</mu>
            <mu2>3.0</mu2>
          </ode>
          <bullet>
            <rolling_friction>0.3</rolling_friction>
            <friction2>3.0</friction2>
          </bullet>
        </friction>
        <contact>
          <bullet>
            <kp>30000.0</kp>
            <kd>1000.0</kd>
          </bullet>
          <ode>
            <kp>30000.0</kp>
            <kd>1000.0</kd>
          </ode>
        </contact>
      </surface>
    </collision>
  </gazebo>
  <joint name="jtoe1_spirit0" type="fixed">
    <parent link="lower1_spirit0" />
    <child link="toe1_spirit0" />
    <origin xyz="0.206 0 -0.0" />
    <dynamics damping="0.0" friction="0.0" />
  </joint>
  
  <link name="hip2_spirit0">
    <visual>
      <origin rpy="1.5707963268 0 0" xyz="0.0 -0.028 0" />
      <geometry>
        <cylinder length="0.08" radius="0.055" />
      </geometry>
      <material name="red" />
    </visual>
    <collision>
      <origin rpy="1.5707963268 0 0" xyz="0 -0.028 0" />
      <geometry>
        <cylinder length="0.08" radius="0.055" />
      </geometry>
    </collision>
    <inertial>
      <mass value="0.575" />
      
      <inertia ixx="0.00066963541" ixy="0" ixz="0" iyy="0.00066963541" iyz="0" izz="0.0008696875" />
    </inertial>
  </link>
  <gazebo reference="hip2">
    <material>Gazebo/Purple</material>
  </gazebo>
  
  <joint name="10_spirit0" type="revolute">
    <parent link="body_spirit0" />
    <child link="hip2_spirit0" />
    <axis xyz="1 0 0" />
    <origin xyz="0.2263 -0.07 0" />
    <limit effort="40" lower="-0.707" upper="0.707" velocity="30" />
    <dynamics damping="0.0" friction="0.0" />
  </joint>
  
  <transmission name="transmission_10">
    <type>transmission_interface/SimpleTransmission</type>
    <joint name="10_spirit0">
      <hardwareInterface>hardware_interface/EffortJointInterface</hardwareInterface>
    </joint>
    <actuator name="motor_10">
      <hardwareInterface>EffortJointInterface</hardwareInterface>
      <mechanicalReduction>1</mechanicalReduction>
    </actuator>
  </transmission>
  
  <link name="upper2_spirit0">
    <visual>
      <origin rpy="0 0 0" xyz="-0.103 0.022 0" />
      <geometry>
        <box size="0.206 0.022 0.055" />
      </geometry>
      <material name="silver" />
    </visual>
    <collision>
      <origin rpy="0 0 0" xyz="-0.103 0.022 0" />
      <geometry>
        <box size="0.206 0.022 0.055" />
      </geometry>
    </collision>
    <inertial>
      <mass value="0.775" />
      <inertia ixx="5e-05" ixy="0" ixz="0" iyy="0.001" iyz="0" izz="0.001" />
    </inertial>
  </link>
  <gazebo reference="upper2">
    <material>Gazebo/Blue</material>
  </gazebo>
  
  <joint name="4_spirit0" type="revolute">
    <parent link="hip2_spirit0" />
    <child link="upper2_spirit0" />
    <axis xyz="0 -1 0" />
    <origin xyz="0.0 -0.10098 0" />
    
    <limit effort="40" lower="-6.28318530718" upper="6.28318530718" velocity="30" />
    <dynamics damping="0.0" friction="0.0" />
  </joint>
  
  <transmission name="transmission_4">
    <type>transmission_interface/SimpleTransmission</type>
    <joint name="4_spirit0">
      <hardwareInterface>hardware_interface/EffortJointInterface</hardwareInterface>
    </joint>
    <actuator name="motor_4">
      <hardwareInterface>EffortJointInterface</hardwareInterface>
      <mechanicalReduction>1</mechanicalReduction>
    </actuator>
  </transmission>
  
  <link name="lower2_spirit0">
    <visual>
      <origin rpy="0 1.5707963268 0" xyz="0.103 0 0" />
      <geometry>
        <cylinder length="0.206" radius="0.013" />
      </geometry>
      <material name="darkgray" />
    </visual>
    <collision>
      <origin rpy="0 1.5707963268 0" xyz="0.103 0 0" />
      <geometry>
        <cylinder length="0.206" radius="0.013" />
      </geometry>
    </collision>
    <inertial>
      <mass value="0.075" />
      <inertia ixx="5e-06" ixy="0" ixz="0" iyy="0.0001" iyz="0" izz="0.0001" />
    </inertial>
  </link>
  <gazebo reference="lower2">
    <material>Gazebo/Black</material>
  </gazebo>
  
  <joint name="5_spirit0" type="revolute">
    <parent link="upper2_spirit0" />
    <child link="lower2_spirit0" />
    <axis xyz="0 1 0" />
    <origin xyz="-0.206 0 0" />
    
    <limit effort="40" velocity="30" />
    <dynamics damping="0.0" friction="0.0" />
  </joint>
  
  <transmission name="transmission_5">
    <type>transmission_interface/SimpleTransmission</type>
    <joint name="5_spirit0">
      <hardwareInterface>hardware_interface/EffortJointInterface</hardwareInterface>
    </joint>
    <actuator name="motor_5">
      <hardwareInterface>EffortJointInterface</hardwareInterface>
      <mechanicalReduction>1</mechanicalReduction>
    </actuator>
  </transmission>
  
  <link name="toe2_spirit0">
    <contact>
      <friction_anchor />
      <stiffness value="30000.0" />
      <damping value="1000.0" />
      <spinning_friction value="0.3" />
      <lateral_friction value="3.0" />
    </contact>
    <visual>
      <origin rpy="0 0 0" xyz="0 0 0" />
      <geometry>
        <sphere radius="0.02" />
      </geometry>
      <material name="darkgray" />
    </visual>
    <collision>
      <origin rpy="0 0 0" xyz="0 0 0" />
      <geometry>
        <sphere radius="0.02" />
      </geometry>
    </collision>
    <inertial>
      <mass value="0.35" />
      <inertia ixx="0.00005" ixy="0" ixz="0" iyy="0.00005" iyz="0" izz="0.00005" />
      
    </inertial>
  </link>
  <gazebo reference="toe2">
    <material>Gazebo/DarkGray</material>
    <collision>
      <surface>
        <bounce>
          <restitution_coefficient>0</restitution_coefficient>
          <threshold>1e+06</threshold>
        </bounce>
        <friction>
          <torsional>
            <coefficient>0.3</coefficient>
          </torsional>
          <ode>
            <mu>20.0</mu>
            <mu2>3.0</mu2>
          </ode>
          <bullet>
            <rolling_friction>0.3</rolling_friction>
            <friction2>3.0</friction2>
          </bullet>
        </friction>
        <contact>
          <bullet>
            <kp>30000.0</kp>
            <kd>1000.0</kd>
          </bullet>
          <ode>
            <kp>30000.0</kp>
            <kd>1000.0</kd>
          </ode>
        </contact>
      </surface>
    </collision>
  </gazebo>
  <joint name="jtoe2_spirit0" type="fixed">
    <parent link="lower2_spirit0" />
    <child link="toe2_spirit0" />
    <origin xyz="0.206 0 -0.0" />
    <dynamics damping="0.0" friction="0.0" />
  </joint>
  
  <link name="hip3_spirit0">
    <visual>
      <origin rpy="1.5707963268 0 0" xyz="-0.0 -0.028 0" />
      <geometry>
        <cylinder length="0.08" radius="0.055" />
      </geometry>
      <material name="darkgray" />
    </visual>
    <collision>
      <origin rpy="1.5707963268 0 0" xyz="0 -0.028 0" />
      <geometry>
        <cylinder length="0.08" radius="0.055" />
      </geometry>
    </collision>
    <inertial>
      <mass value="0.575" />
      
      <inertia ixx="0.00066963541" ixy="0" ixz="0" iyy="0.00066963541" iyz="0" izz="0.0008696875" />
    </inertial>
  </link>
  <gazebo reference="hip3">
    <material>Gazebo/Purple</material>
  </gazebo>
  
  <joint name="11_spirit0" type="revolute">
    <parent link="body_spirit0" />
    <child link="hip3_spirit0" />
    <axis xyz="1 0 0" />
    <origin xyz="-0.2263 -0.07 0" />
    <limit effort="40" lower="-0.707" upper="0.707" velocity="30" />
    <dynamics damping="0.0" friction="0.0" />
  </joint>
  
  <transmission name="transmission_11">
    <type>transmission_interface/SimpleTransmission</type>
    <joint name="11_spirit0">
      <hardwareInterface>hardware_interface/EffortJointInterface</hardwareInterface>
    </joint>
    <actuator name="motor_11">
      <hardwareInterface>EffortJointInterface</hardwareInterface>
      <mechanicalReduction>1</mechanicalReduction>
    </actuator>
  </transmission>
  
  <link name="upper3_spirit0">
    <visual>
      <origin rpy="0 0 0" xyz="-0.103 0.022 0" />
      <geometry>
        <box size="0.206 0.022 0.055" />
      </geometry>
      <material name="silver" />
    </visual>
    <collision>
      <origin rpy="0 0 0" xyz="-0.103 0.022 0" />
      <geometry>
        <box size="0.206 0.022 0.055" />
      </geometry>
    </collision>
    <inertial>
      <mass value="0.775" />
      <inertia ixx="5e-05" ixy="0" ixz="0" iyy="0.001" iyz="0" izz="0.001" />
    </inertial>
  </link>
  <gazebo reference="upper3">
    <material>Gazebo/Blue</material>
  </gazebo>
  
  <joint name="6_spirit0" type="revolute">
    <parent link="hip3_spirit0" />
    <child link="upper3_spirit0" />
    <axis xyz="0 -1 0" />
    <origin xyz="-0.0 -0.10098 0" />
    
    <limit effort="40" lower="-6.28318530718" upper="6.28318530718" velocity="30" />
    <dynamics damping="0.0" friction="0.0" />
  </joint>
  
  <transmission name="transmission_6">
    <type>transmission_interface/SimpleTransmission</type>
    <joint name="6_spirit0">
      <hardwareInterface>hardware_interface/EffortJointInterface</hardwareInterface>
    </joint>
    <actuator name="motor_6">
      <hardwareInterface>EffortJointInterface</hardwareInterface>
      <mechanicalReduction>1</mechanicalReduction>
    </actuator>
  </transmission>
  
  <link name="lower3_spirit0">
    <visual>
      <origin rpy="0 1.5707963268 0" xyz="0.103 0 0" />
      <geometry>
        <cylinder length="0.206" radius="0.013" />
      </geometry>
      <material name="darkgray" />
    </visual>
    <collision>
      <origin rpy="0 1.5707963268 0" xyz="0.103 0 0" />
      <geometry>
        <cylinder length="0.206" radius="0.013" />
      </geometry>
    </collision>
    <inertial>
      <mass value="0.075" />
      <inertia ixx="5e-06" ixy="0" ixz="0" iyy="0.0001" iyz="0" izz="0.0001" />
    </inertial>
  </link>
  <gazebo reference="lower3">
    <material>Gazebo/Black</material>
  </gazebo>
  
  <joint name="7_spirit0" type="revolute">
    <parent link="upper3_spirit0" />
    <child link="lower3_spirit0" />
    <axis xyz="0 1 0" />
    <origin xyz="-0.206 0 0" />
    
    <limit effort="40" velocity="30" />
    <dynamics damping="0.0" friction="0.0" />
  </joint>
  
  <transmission name="transmission_7">
    <type>transmission_interface/SimpleTransmission</type>
    <joint name="7_spirit0">
      <hardwareInterface>hardware_interface/EffortJointInterface</hardwareInterface>
    </joint>
    <actuator name="motor_7">
      <hardwareInterface>EffortJointInterface</hardwareInterface>
      <mechanicalReduction>1</mechanicalReduction>
    </actuator>
  </transmission>
  
  <link name="toe3_spirit0">
    <contact>
      <friction_anchor />
      <stiffness value="30000.0" />
      <damping value="1000.0" />
      <spinning_friction value="0.3" />
      <lateral_friction value="3.0" />
    </contact>
    <visual>
      <origin rpy="0 0 0" xyz="0 0 0" />
      <geometry>
        <sphere radius="0.02" />
      </geometry>
      <material name="darkgray" />
    </visual>
    <collision>
      <origin rpy="0 0 0" xyz="0 0 0" />
      <geometry>
        <sphere radius="0.02" />
      </geometry>
    </collision>
    <inertial>
      <mass value="0.35" />
      <inertia ixx="0.00005" ixy="0" ixz="0" iyy="0.00005" iyz="0" izz="0.00005" />
      
    </inertial>
  </link>
  <gazebo reference="toe3">
    <material>Gazebo/DarkGray</material>
    <collision>
      <surface>
        <bounce>
          <restitution_coefficient>0</restitution_coefficient>
          <threshold>1e+06</threshold>
        </bounce>
        <friction>
          <torsional>
            <coefficient>0.3</coefficient>
          </torsional>
          <ode>
            <mu>20.0</mu>
            <mu2>3.0</mu2>
          </ode>
          <bullet>
            <rolling_friction>0.3</rolling_friction>
            <friction2>3.0</friction2>
          </bullet>
        </friction>
        <contact>
          <bullet>
            <kp>30000.0</kp>
            <kd>1000.0</kd>
          </bullet>
          <ode>
            <kp>30000.0</kp>
            <kd>1000.0</kd>
          </ode>
        </contact>
      </surface>
    </collision>
  </gazebo>
  <joint name="jtoe3_spirit0" type="fixed">
    <parent link="lower3_spirit0" />
    <child link="toe3_spirit0" />
    <origin xyz="0.206 0 -0.0" />
    <dynamics damping="0.0" friction="0.0" />
  </joint>
  
  <gazebo>
    <plugin filename="libgazebo_ros_control.so" name="gazebo_ros_control">
      <robotNamespace>/spirit</robotNamespace>
    </plugin>
  </gazebo>
</robot>